0.000s : Process 1 arrived
0.000s : Context switching to pid: 1
0.000s : Process 2 arrived
0.000s : Process 3 arrived

0.006s : Process 4 arrived

0.024s : Process 5 arrived

0.065s : Process 6 arrived
0.065s : Process 7 arrived

0.196s : Process 1 has finished execution and is exiting
0.196s : Context switching to pid: 2

0.208s : Process 2 has finished execution and is exiting
0.208s : Context switching to pid: 3

0.265s : Process 8 arrived

0.396s : Process 3 has finished execution and is exiting
0.396s : Context switching to pid: 4

0.422s : Process 4 has finished execution and is exiting
0.422s : Context switching to pid: 5

0.452s : Process 5 has finished execution and is exiting
0.452s : Context switching to pid: 6

0.483s : Process 9 arrived
0.483s : Process 10 arrived
0.483s : Process 11 arrived

0.493s : Process 6 has finished execution and is exiting
0.493s : Context switching to pid: 7

0.520s : Process 12 arrived

0.566s : Process 13 arrived
0.566s : Process 14 arrived
0.566s : Process 15 arrived

0.576s : Process 7 has finished execution and is exiting
0.576s : Context switching to pid: 8

0.590s : Process 16 arrived
0.590s : Process 17 arrived
0.590s : Process 18 arrived
0.590s : Process 19 arrived
0.590s : Process 20 arrived
0.590s : Process 21 arrived

0.631s : Process 8 has finished execution and is exiting
0.631s : Context switching to pid: 9

0.731s : Process 9 has finished execution and is exiting
0.731s : Context switching to pid: 10

0.756s : Process 10 has finished execution and is exiting
0.756s : Context switching to pid: 11

0.856s : Process 11 has finished execution and is exiting
0.856s : Context switching to pid: 12

0.967s : Process 22 arrived

1.003s : Process 12 has finished execution and is exiting
1.003s : Context switching to pid: 13

1.013s : Process 23 arrived
1.013s : Process 24 arrived

1.044s : Process 13 has finished execution and is exiting
1.044s : Context switching to pid: 14

1.047s : Process 25 arrived

1.184s : Process 14 has finished execution and is exiting
1.184s : Context switching to pid: 15

1.221s : Process 15 has finished execution and is exiting
1.221s : Context switching to pid: 16

1.225s : Process 16 has finished execution and is exiting
1.225s : Context switching to pid: 17

1.262s : Process 17 has finished execution and is exiting
1.262s : Context switching to pid: 18

1.378s : Process 18 has finished execution and is exiting
1.378s : Context switching to pid: 19

1.383s : Process 19 has finished execution and is exiting
1.383s : Context switching to pid: 20

1.524s : Process 20 has finished execution and is exiting
1.524s : Context switching to pid: 21

1.641s : Process 21 has finished execution and is exiting
1.641s : Context switching to pid: 22

1.642s : Process 22 has finished execution and is exiting
1.642s : Context switching to pid: 23

1.704s : Process 23 has finished execution and is exiting
1.704s : Context switching to pid: 24

1.710s : Process 24 has finished execution and is exiting
1.710s : Context switching to pid: 25

1.761s : Process 25 has finished execution and is exiting
1.761s : Context switching to pid: 0

